<?xml version="1.0" encoding="utf-8"?>
<robot xmlns:xacro="http://wiki.ros.org/xacro">
  <!-- Properties -->
  <xacro:property name="joint_limits" value="${xacro.load_yaml(joint_limits_file)['joint_limits']}" />

  <!-- Links and Joints -->
  <!-- base_link serves as the root of the robot's kinematic tree. It follows REP-103
        conventions (i.e., X+ forward, Y+ left, Z+ up).
        Since some kinematic solvers forbid having inertia values attached to a root link, we've
        added the base_link_inertia link that carries the visual, collision and inertia
        information.
    -->
  <link name="${tf_prefix}base_link" />
  <link name="${tf_prefix}base_link_inertia">
    <inertial>
      <origin
        xyz="-0.00043295 -3.5277E-05 0.059942"
        rpy="0 0 0" />
      <mass
        value="0.84105" />
      <inertia
        ixx="0.0017261"
        ixy="2.5273E-06"
        ixz="-3.6769E-05"
        iyy="0.0017099"
        iyz="1.6802E-06"
        izz="0.00090402" />
    </inertial>
    <visual>
      <origin
        xyz="0 0 0"
        rpy="0 0 0" />
      <geometry>
        <mesh
          filename="package://rm_xacro_description/meshes/rm_65_arm/base_link.STL" />
      </geometry>
      <material
        name="">
        <color
          rgba="1 1 1 1" />
      </material>
    </visual>
    <collision>
      <origin
        xyz="0 0 0"
        rpy="0 0 0" />
      <geometry>
        <mesh
          filename="package://rm_xacro_description/meshes/rm_65_arm/base_link.STL" />
      </geometry>
    </collision>
  </link>

  <joint name="${tf_prefix}base_link-base_link_inertia" type="fixed">
    <parent link="${tf_prefix}base_link" />
    <child link="${tf_prefix}base_link_inertia" />
    <origin xyz="0 0 0" rpy="0 0 0" />
  </joint>

  <!-- base_joint fixes base_link to the environment -->
  <joint name="${tf_prefix}base_joint" type="fixed">
    <xacro:insert_block name="origin" />
    <parent link="${parent}" />
    <child link="${tf_prefix}base_link" />
  </joint>

  <link
    name="${tf_prefix}Link1">
    <inertial>
      <origin
        xyz="2.1376E-07 0.021108 -0.025186"
        rpy="0 0 0" />
      <mass
        value="0.59356" />
      <inertia
        ixx="0.0012661"
        ixy="-1.2951E-08"
        ixz="-9.8019E-09"
        iyy="0.0011817"
        iyz="-0.00021122"
        izz="0.00056135" />
    </inertial>
    <visual>
      <origin
        xyz="0 0 0"
        rpy="0 0 0" />
      <geometry>
        <mesh
          filename="package://rm_xacro_description/meshes/rm_65_arm/link1.STL" />
      </geometry>
      <material
        name="">
        <color
          rgba="1 1 1 1" />
      </material>
    </visual>
    <collision>
      <origin
        xyz="0 0 0"
        rpy="0 0 0" />
      <geometry>
        <mesh
          filename="package://rm_xacro_description/meshes/rm_65_arm/link1.STL" />
      </geometry>
    </collision>
  </link>
  <joint
    name="${tf_prefix}joint1"
    type="revolute">
    <origin
      xyz="0 0 0.2405"
      rpy="0 0 0" />
    <parent
      link="${tf_prefix}base_link" />
    <child
      link="${tf_prefix}Link1" />
    <axis
      xyz="0 0 1" />
    <limit
      lower="${joint_limits['joint1']['min_position']}"
      upper="${joint_limits['joint1']['max_position']}"
      velocity="${joint_limits['joint1']['max_velocity']}"
      effort="${joint_limits['joint1']['max_effort']}"
    />
  </joint>
  <link
    name="${tf_prefix}Link2">
    <inertial>
      <origin
        xyz="0.15226 6.0139E-07 -0.0062025"
        rpy="0 0 0" />
      <mass
        value="0.86418" />
      <inertia
        ixx="0.00063254"
        ixy="-5.979E-09"
        ixz="0.00042163"
        iyy="0.0020527"
        iyz="1.8401E-09"
        izz="0.0019528" />
    </inertial>
    <visual>
      <origin
        xyz="0 0 0"
        rpy="0 0 0" />
      <geometry>
        <mesh
          filename="package://rm_xacro_description/meshes/rm_65_arm/link2.STL" />
      </geometry>
      <material
        name="">
        <color
          rgba="1 1 1 1" />
      </material>
    </visual>
    <collision>
      <origin
        xyz="0 0 0"
        rpy="0 0 0" />
      <geometry>
        <mesh
          filename="package://rm_xacro_description/meshes/rm_65_arm/link2.STL" />
      </geometry>
    </collision>
  </link>
  <joint
    name="${tf_prefix}joint2"
    type="revolute">
    <origin
      xyz="0 0 0"
      rpy="1.5708 -1.5708 0" />
    <parent
      link="${tf_prefix}Link1" />
    <child
      link="${tf_prefix}Link2" />
    <axis
      xyz="0 0 1" />
    <limit
      lower="${joint_limits['joint2']['min_position']}"
      upper="${joint_limits['joint2']['max_position']}"
      velocity="${joint_limits['joint2']['max_velocity']}"
      effort="${joint_limits['joint2']['max_effort']}"
    />
  </joint>
  <link
    name="${tf_prefix}Link3">
    <inertial>
      <origin
        xyz="5.0421E-06 -0.059593 0.010569"
        rpy="0 0 0" />
      <mass
        value="0.28963" />
      <inertia
        ixx="0.00063737"
        ixy="-7.0522E-08"
        ixz="-3.8666E-08"
        iyy="0.00015648"
        iyz="-0.00014461"
        izz="0.00061418" />
    </inertial>
    <visual>
      <origin
        xyz="0 0 0"
        rpy="0 0 0" />
      <geometry>
        <mesh
          filename="package://rm_xacro_description/meshes/rm_65_arm/link3.STL" />
      </geometry>
      <material
        name="">
        <color
          rgba="1 1 1 1" />
      </material>
    </visual>
    <collision>
      <origin
        xyz="0 0 0"
        rpy="0 0 0" />
      <geometry>
        <mesh
          filename="package://rm_xacro_description/meshes/rm_65_arm/link3.STL" />
      </geometry>
    </collision>
  </link>
  <joint
    name="${tf_prefix}joint3"
    type="revolute">
    <origin
      xyz="0.256 0 0"
      rpy="0 0 1.5708" />
    <parent
      link="${tf_prefix}Link2" />
    <child
      link="${tf_prefix}Link3" />
    <axis
      xyz="0 0 1" />
    <limit
      lower="${joint_limits['joint3']['min_position']}"
      upper="${joint_limits['joint3']['max_position']}"
      velocity="${joint_limits['joint3']['max_velocity']}"
      effort="${joint_limits['joint3']['max_effort']}"
    />
  </joint>
  <link
    name="${tf_prefix}Link4">
    <inertial>
      <origin
        xyz="1.1466E-06 -0.018041 -0.021541"
        rpy="0 0 0" />
      <mass
        value="0.23941" />
      <inertia
        ixx="0.00028594"
        ixy="2.6611E-09"
        ixz="-1.8435E-09"
        iyy="0.00026273"
        iyz="4.4238E-05"
        izz="0.00011989" />
    </inertial>
    <visual>
      <origin
        xyz="0 0 0"
        rpy="0 0 0" />
      <geometry>
        <mesh
          filename="package://rm_xacro_description/meshes/rm_65_arm/link4.STL" />
      </geometry>
      <material
        name="">
        <color
          rgba="1 1 1 1" />
      </material>
    </visual>
    <collision>
      <origin
        xyz="0 0 0"
        rpy="0 0 0" />
      <geometry>
        <mesh
          filename="package://rm_xacro_description/meshes/rm_65_arm/link4.STL" />
      </geometry>
    </collision>
  </link>
  <joint
    name="${tf_prefix}joint4"
    type="revolute">
    <origin
      xyz="0 -0.21 0"
      rpy="1.5708 0 0" />
    <parent
      link="${tf_prefix}Link3" />
    <child
      link="${tf_prefix}Link4" />
    <axis
      xyz="0 0 1" />
    <limit
      lower="${joint_limits['joint4']['min_position']}"
      upper="${joint_limits['joint4']['max_position']}"
      velocity="${joint_limits['joint4']['max_velocity']}"
      effort="${joint_limits['joint4']['max_effort']}"
    />
  </joint>
  <link
    name="${tf_prefix}Link5">
    <inertial>
      <origin
        xyz="3.4542E-06 -0.059382 0.0073678"
        rpy="0 0 0" />
      <mass
        value="0.21879" />
      <inertia
        ixx="0.00035053"
        ixy="-3.1667E-08"
        ixz="-1.7442E-08"
        iyy="0.00010492"
        iyz="-7.824E-05"
        izz="0.00033447" />
    </inertial>
    <visual>
      <origin
        xyz="0 0 0"
        rpy="0 0 0" />
      <geometry>
        <mesh
          filename="package://rm_xacro_description/meshes/rm_65_arm/link5.STL" />
      </geometry>
      <material
        name="">
        <color
          rgba="1 1 1 1" />
      </material>
    </visual>
    <collision>
      <origin
        xyz="0 0 0"
        rpy="0 0 0" />
      <geometry>
        <mesh
          filename="package://rm_xacro_description/meshes/rm_65_arm/link5.STL" />
      </geometry>
    </collision>
  </link>
  <joint
    name="${tf_prefix}joint5"
    type="revolute">
    <origin
      xyz="0 0 0"
      rpy="-1.5708 0 0" />
    <parent
      link="${tf_prefix}Link4" />
    <child
      link="${tf_prefix}Link5" />
    <axis
      xyz="0 0 1" />
    <limit
      lower="${joint_limits['joint5']['min_position']}"
      upper="${joint_limits['joint5']['max_position']}"
      velocity="${joint_limits['joint5']['max_velocity']}"
      effort="${joint_limits['joint5']['max_effort']}"
    />
  </joint>
  <link
    name="${tf_prefix}Link6">
    <inertial>
      <origin
        xyz="0.00032231 -0.00017819 -0.028676"
        rpy="0 0 0" />
      <mass
        value="0.14433" />
      <inertia
        ixx="3.6119E-05"
        ixy="-1.3242E-06"
        ixz="-3.2733E-08"
        iyy="3.4626E-05"
        iyz="7.6661E-09"
        izz="6.1463E-05" />
    </inertial>
    <visual>
      <origin
        xyz="0 0 0"
        rpy="0 0 0" />
      <geometry>
        <mesh
          filename="package://rm_xacro_description/meshes/rm_65_arm/link6_6f.STL" />
      </geometry>
      <material
        name="">
        <color
          rgba="1 1 1 1" />
      </material>
    </visual>
    <collision>
      <origin
        xyz="0 0 0"
        rpy="0 0 0" />
      <geometry>
        <mesh
          filename="package://rm_xacro_description/meshes/rm_65_arm/link6_6f.STL" />
      </geometry>
    </collision>
  </link>
  <joint
    name="${tf_prefix}joint6"
    type="revolute">
    <origin
      xyz="0 -0.1725 0"
      rpy="1.5708 0 0" />
    <parent
      link="${tf_prefix}Link5" />
    <child
      link="${tf_prefix}Link6" />
    <axis
      xyz="0 0 1" />
    <limit
      lower="${joint_limits['joint6']['min_position']}"
      upper="${joint_limits['joint6']['max_position']}"
      velocity="${joint_limits['joint6']['max_velocity']}"
      effort="${joint_limits['joint6']['max_effort']}"
    />
  </joint>

  <!-- ROS-Industrial 'base' frame - base_link to RM 'Base' Coordinates transform -->
  <link name="${tf_prefix}base" />
  <joint name="${tf_prefix}base_link-base_fixed_joint" type="fixed">
    <!-- TODO -->
    <origin xyz="0 0 0" rpy="0 0 0" />
    <parent link="${tf_prefix}base_link" />
    <child link="${tf_prefix}base" />
  </joint>

  <!-- ROS-Industrial 'flange' frame - attachment point for EEF models -->
  <link name="${tf_prefix}flange" />
  <joint name="${tf_prefix}Link7-flange" type="fixed">
    <!-- TODO -->
    <origin xyz="0 0 0" rpy="0 0 0" />
    <parent link="${tf_prefix}Link6" />
    <child link="${tf_prefix}flange" />
  </joint>

  <!-- ROS-Industrial 'tool0' frame - all-zeros tool frame -->
  <link name="${tf_prefix}tool0" />
  <joint name="${tf_prefix}flange-tool0" type="fixed">
    <!-- TODO -->
    <origin xyz="0 0 0" rpy="0 0 0" />
    <parent link="${tf_prefix}flange" />
    <child link="${tf_prefix}tool0" />
  </joint>
</robot>