<?xml version="1.0" encoding="utf-8"?>
<robot xmlns:xacro="http://wiki.ros.org/xacro">
  <!-- Properties -->
  <xacro:property name="joint_limits" value="${xacro.load_yaml(joint_limits_file)['joint_limits']}" />

  <!-- Links and Joints -->
  <!-- base_link serves as the root of the robot's kinematic tree. It follows REP-103
        conventions (i.e., X+ forward, Y+ left, Z+ up).
        Since some kinematic solvers forbid having inertia values attached to a root link, we've
        added the base_link_inertia link that carries the visual, collision and inertia
        information.
    -->
  <link name="${tf_prefix}base_link" />
  <link name="${tf_prefix}base_link_inertia">
    <inertial>
      <origin
        xyz="0.000433268851866144 3.54527840972405E-05 0.0599427623574736"
        rpy="0 0 0" />
      <mass
        value="0.841071174772543" />
      <inertia
        ixx="0.00172611149818605"
        ixy="2.52724703312125E-06"
        ixz="3.67689528877993E-05"
        iyy="0.00170987425756066"
        iyz="-1.68009023667311E-06"
        izz="0.000904023916742301" />
    </inertial>
    <visual>
      <origin
        xyz="0 0 0"
        rpy="0 0 0" />
      <geometry>
        <mesh
          filename="package://rm_xacro_description/meshes/rm_75_arm/base_link.STL" />
      </geometry>
      <material
        name="">
        <color
          rgba="1 1 1 1" />
      </material>
    </visual>
    <collision>
      <origin
        xyz="0 0 0"
        rpy="0 0 0" />
      <geometry>
        <mesh
          filename="package://rm_xacro_description/meshes/rm_75_arm/base_link.STL" />
      </geometry>
    </collision>
  </link>

  <joint name="${tf_prefix}base_link-base_link_inertia" type="fixed">
    <parent link="${tf_prefix}base_link" />
    <child link="${tf_prefix}base_link_inertia" />
    <origin xyz="0 0 0" rpy="0 0 0" />
  </joint>

  <!-- base_joint fixes base_link to the environment -->
  <joint name="${tf_prefix}base_joint" type="fixed">
    <xacro:insert_block name="origin" />
    <parent link="${parent}" />
    <child link="${tf_prefix}base_link" />
  </joint>

  <link
    name="${tf_prefix}Link1">
    <inertial>
      <origin
        xyz="0.0251854224372461 1.19160585601655E-08 -0.021107996993288"
        rpy="0 0 0" />
      <mass
        value="0.593563458735581" />
      <inertia
        ixx="0.000561352422092522"
        ixy="9.8019294192418E-09"
        ixz="-0.000211217278563478"
        iyy="0.00126614121202124"
        iyz="1.29510293158304E-08"
        izz="0.0011816817861243" />
    </inertial>
    <visual>
      <origin
        xyz="0 0 0"
        rpy="0 0 0" />
      <geometry>
        <mesh
          filename="package://rm_xacro_description/meshes/rm_75_arm/link1.STL" />
      </geometry>
      <material
        name="">
        <color
          rgba="1 1 1 1" />
      </material>
    </visual>
    <collision>
      <origin
        xyz="0 0 0"
        rpy="0 0 0" />
      <geometry>
        <mesh
          filename="package://rm_xacro_description/meshes/rm_75_arm/link1.STL" />
      </geometry>
    </collision>
  </link>
  <joint
    name="${tf_prefix}joint1"
    type="revolute">
    <origin
      xyz="0 0 0.2405"
      rpy="-1.5708 0 0" />
    <parent
      link="${tf_prefix}base_link" />
    <child
      link="${tf_prefix}Link1" />
    <axis
      xyz="0 -1 0" />
    <limit
      lower="${joint_limits['joint1']['min_position']}"
      upper="${joint_limits['joint1']['max_position']}"
      velocity="${joint_limits['joint1']['max_velocity']}"
      effort="${joint_limits['joint1']['max_effort']}"
    />
  </joint>
  <link
    name="${tf_prefix}Link2">
    <inertial>
      <origin
        xyz="2.72859133252335E-07 0.011077753037361 0.0761295106490881"
        rpy="0 0 0" />
      <mass
        value="0.432849770310974" />
      <inertia
        ixx="0.00125838173873093"
        ixy="5.63146579602116E-09"
        ixz="1.33486683063366E-09"
        iyy="0.00122245448121472"
        iyz="0.000279003475762058"
        izz="0.000317474184276672" />
    </inertial>
    <visual>
      <origin
        xyz="0 0 0"
        rpy="0 0 0" />
      <geometry>
        <mesh
          filename="package://rm_xacro_description/meshes/rm_75_arm/link2.STL" />
      </geometry>
      <material
        name="">
        <color
          rgba="1 1 1 1" />
      </material>
    </visual>
    <collision>
      <origin
        xyz="0 0 0"
        rpy="0 0 0" />
      <geometry>
        <mesh
          filename="package://rm_xacro_description/meshes/rm_75_arm/link2.STL" />
      </geometry>
    </collision>
  </link>
  <joint
    name="${tf_prefix}joint2"
    type="revolute">
    <origin
      xyz="0 0 0"
      rpy="1.5708 0 0" />
    <parent
      link="${tf_prefix}Link1" />
    <child
      link="${tf_prefix}Link2" />
    <axis
      xyz="0 1 0" />
    <limit
      lower="${joint_limits['joint2']['min_position']}"
      upper="${joint_limits['joint2']['max_position']}"
      velocity="${joint_limits['joint2']['max_velocity']}"
      effort="${joint_limits['joint2']['max_effort']}"
    />
  </joint>
  <link
    name="${tf_prefix}Link3">
    <inertial>
      <origin
        xyz="6.84676164566044E-07 0.0273475408308154 -0.0235440119707943"
        rpy="0 0 0" />
      <mass
        value="0.431325495678459" />
      <inertia
        ixx="0.000794332771462568"
        ixy="1.03353218375171E-08"
        ixz="-2.32798826854953E-09"
        iyy="0.000315065343266245"
        iyz="-0.000142620540462618"
        izz="0.000730371131605455" />
    </inertial>
    <visual>
      <origin
        xyz="0 0 0"
        rpy="0 0 0" />
      <geometry>
        <mesh
          filename="package://rm_xacro_description/meshes/rm_75_arm/link3.STL" />
      </geometry>
      <material
        name="">
        <color
          rgba="1 1 1 1" />
      </material>
    </visual>
    <collision>
      <origin
        xyz="0 0 0"
        rpy="0 0 0" />
      <geometry>
        <mesh
          filename="package://rm_xacro_description/meshes/rm_75_arm/link3.STL" />
      </geometry>
    </collision>
  </link>
  <joint
    name="${tf_prefix}joint3"
    type="revolute">
    <origin
      xyz="0 0 0.256"
      rpy="-1.5708 0 0" />
    <parent
      link="${tf_prefix}Link2" />
    <child
      link="${tf_prefix}Link3" />
    <axis
      xyz="0 -1 0" />
    <limit
      lower="${joint_limits['joint3']['min_position']}"
      upper="${joint_limits['joint3']['max_position']}"
      velocity="${joint_limits['joint3']['max_velocity']}"
      effort="${joint_limits['joint3']['max_effort']}"
    />
  </joint>
  <link
    name="${tf_prefix}Link4">
    <inertial>
      <origin
        xyz="5.05312670298932E-06 0.0105690692118619 0.0595925663703773"
        rpy="0 0 0" />
      <mass
        value="0.289633681619295" />
      <inertia
        ixx="0.000637371004484591"
        ixy="-3.86643270900744E-08"
        ixz="7.05261290886955E-08"
        iyy="0.000614178164759844"
        iyz="0.000144610359942128"
        izz="0.000156483880946498" />
    </inertial>
    <visual>
      <origin
        xyz="0 0 0"
        rpy="0 0 0" />
      <geometry>
        <mesh
          filename="package://rm_xacro_description/meshes/rm_75_arm/link4.STL" />
      </geometry>
      <material
        name="">
        <color
          rgba="1 1 1 1" />
      </material>
    </visual>
    <collision>
      <origin
        xyz="0 0 0"
        rpy="0 0 0" />
      <geometry>
        <mesh
          filename="package://rm_xacro_description/meshes/rm_75_arm/link4.STL" />
      </geometry>
    </collision>
  </link>
  <joint
    name="${tf_prefix}joint4"
    type="revolute">
    <origin
      xyz="0 0 0"
      rpy="1.5708 0 0" />
    <parent
      link="${tf_prefix}Link3" />
    <child
      link="${tf_prefix}Link4" />
    <axis
      xyz="0 1 0" />
    <limit
      lower="${joint_limits['joint4']['min_position']}"
      upper="${joint_limits['joint4']['max_position']}"
      velocity="${joint_limits['joint4']['max_velocity']}"
      effort="${joint_limits['joint4']['max_effort']}"
    />
  </joint>
  <link
    name="${tf_prefix}Link5">
    <inertial>
      <origin
        xyz="1.1551661767744E-06 0.0215394748352686 -0.0180424468598241"
        rpy="0 0 0" />
      <mass
        value="0.239419768320061" />
      <inertia
        ixx="0.000285938919722783"
        ixy="2.21994116852616E-09"
        ixz="3.07101358617598E-09"
        iyy="0.00011988808279186"
        iyz="-4.4236583260078E-05"
        izz="0.000262727540304212" />
    </inertial>
    <visual>
      <origin
        xyz="0 0 0"
        rpy="0 0 0" />
      <geometry>
        <mesh
          filename="package://rm_xacro_description/meshes/rm_75_arm/link5.STL" />
      </geometry>
      <material
        name="">
        <color
          rgba="1 1 1 1" />
      </material>
    </visual>
    <collision>
      <origin
        xyz="0 0 0"
        rpy="0 0 0" />
      <geometry>
        <mesh
          filename="package://rm_xacro_description/meshes/rm_75_arm/link5.STL" />
      </geometry>
    </collision>
  </link>
  <joint
    name="${tf_prefix}joint5"
    type="revolute">
    <origin
      xyz="0 0 0.21"
      rpy="-1.5708 0 0" />
    <parent
      link="${tf_prefix}Link4" />
    <child
      link="${tf_prefix}Link5" />
    <axis
      xyz="0 -1 0" />
    <limit
      lower="${joint_limits['joint5']['min_position']}"
      upper="${joint_limits['joint5']['max_position']}"
      velocity="${joint_limits['joint5']['max_velocity']}"
      effort="${joint_limits['joint5']['max_effort']}"
    />
  </joint>
  <link
    name="${tf_prefix}Link6">
    <inertial>
      <origin
        xyz="3.19794787018954E-06 0.00736804250989373 0.0593808368101291"
        rpy="0 0 0" />
      <mass
        value="0.218799761431682" />
      <inertia
        ixx="0.000350540363914436"
        ixy="-1.7705645712277E-08"
        ixz="3.41781620449632E-08"
        iyy="0.000334482418423991"
        iyz="7.82431228462317E-05"
        izz="0.000104927867487584" />
    </inertial>
    <visual>
      <origin
        xyz="0 0 0"
        rpy="0 0 0" />
      <geometry>
        <mesh
          filename="package://rm_xacro_description/meshes/rm_75_arm/link6.STL" />
      </geometry>
      <material
        name="">
        <color
          rgba="1 1 1 1" />
      </material>
    </visual>
    <collision>
      <origin
        xyz="0 0 0"
        rpy="0 0 0" />
      <geometry>
        <mesh
          filename="package://rm_xacro_description/meshes/rm_75_arm/link6.STL" />
      </geometry>
    </collision>
  </link>
  <joint
    name="${tf_prefix}joint6"
    type="revolute">
    <origin
      xyz="0 0 0"
      rpy="1.5708 0 0" />
    <parent
      link="${tf_prefix}Link5" />
    <child
      link="${tf_prefix}Link6" />
    <axis
      xyz="0 1 0" />
    <limit
      lower="${joint_limits['joint6']['min_position']}"
      upper="${joint_limits['joint6']['max_position']}"
      velocity="${joint_limits['joint6']['max_velocity']}"
      effort="${joint_limits['joint6']['max_effort']}"
    />
  </joint>
  <link
    name="${tf_prefix}Link7">
    <inertial>
      <origin
        xyz="0.000714238382876259 -0.000396711987952758 -0.0126723660946126"
        rpy="0 0 0" />
      <mass
        value="0.0649018034311231" />
      <inertia
        ixx="2.02766547502765E-05"
        ixy="-1.32505200276848E-06"
        ixz="-2.58450915224912E-08"
        iyy="1.87986725225022E-05"
        iyz="3.39471452123283E-09"
        izz="3.17885459163081E-05" />
    </inertial>
    <visual>
      <origin
        xyz="0 0 0"
        rpy="0 0 0" />
      <geometry>
        <mesh
          filename="package://rm_xacro_description/meshes/rm_75_arm/link7.STL" />
      </geometry>
      <material
        name="">
        <color
          rgba="1 1 1 1" />
      </material>
    </visual>
    <collision>
      <origin
        xyz="0 0 0"
        rpy="0 0 0" />
      <geometry>
        <mesh
          filename="package://rm_xacro_description/meshes/rm_75_arm/link7.STL" />
      </geometry>
    </collision>
  </link>
  <joint
    name="${tf_prefix}joint7"
    type="revolute">
    <origin
      xyz="0 0 0.144"
      rpy="0 0 0" />
    <parent
      link="${tf_prefix}Link6" />
    <child
      link="${tf_prefix}Link7" />
    <axis
      xyz="0 0 1" />
    <limit
      lower="${joint_limits['joint7']['min_position']}"
      upper="${joint_limits['joint7']['max_position']}"
      velocity="${joint_limits['joint7']['max_velocity']}"
      effort="${joint_limits['joint7']['max_effort']}"
    />
  </joint>

  <!-- ROS-Industrial 'base' frame - base_link to RM 'Base' Coordinates transform -->
  <link name="${tf_prefix}base" />
  <joint name="${tf_prefix}base_link-base_fixed_joint" type="fixed">
    <!-- TODO -->
    <origin xyz="0 0 0" rpy="0 0 0" />
    <parent link="${tf_prefix}base_link" />
    <child link="${tf_prefix}base" />
  </joint>

  <!-- ROS-Industrial 'flange' frame - attachment point for EEF models -->
  <link name="${tf_prefix}flange" />
  <joint name="${tf_prefix}Link7-flange" type="fixed">
    <!-- TODO -->
    <origin xyz="0 0 0" rpy="0 0 0" />
    <parent link="${tf_prefix}Link7" />
    <child link="${tf_prefix}flange" />
  </joint>

  <!-- ROS-Industrial 'tool0' frame - all-zeros tool frame -->
  <link name="${tf_prefix}tool0" />
  <joint name="${tf_prefix}flange-tool0" type="fixed">
    <!-- TODO -->
    <origin xyz="0 0 0" rpy="0 0 0" />
    <parent link="${tf_prefix}flange" />
    <child link="${tf_prefix}tool0" />
  </joint>
</robot>